{"time":"2024-10-22 11:07:58","level":"ERROR","module":"__init__","method":"global_exception_logger","line":20,"path":"\/opt\/anaconda3\/lib\/python3.12\/site-packages\/anaconda_navigator\/utils\/logs\/__init__.py","message":"HTTPSConnectionPool(host='anaconda.cloud', port=443): Max retries exceeded with url: \/api\/account (Caused by NameResolutionError(\"<urllib3.connection.HTTPSConnection object at 0x11a21a3f0>: Failed to resolve 'anaconda.cloud' ([Errno 8] nodename nor servname provided, or not known)\"))","exception":"Traceback (most recent call last):\n  File \"\/opt\/anaconda3\/lib\/python3.12\/site-packages\/urllib3\/connection.py\", line 196, in _new_conn\n    sock = connection.create_connection(\n           ^^^^^^^^^^^^^^^^^^^^^^^^^^^^^\n  File \"\/opt\/anaconda3\/lib\/python3.12\/site-packages\/urllib3\/util\/connection.py\", line 60, in create_connection\n    for res in socket.getaddrinfo(host, port, family, socket.SOCK_STREAM):\n               ^^^^^^^^^^^^^^^^^^^^^^^^^^^^^^^^^^^^^^^^^^^^^^^^^^^^^^^^^^\n  File \"\/opt\/anaconda3\/lib\/python3.12\/socket.py\", line 963, in getaddrinfo\n    for res in _socket.getaddrinfo(host, port, family, type, proto, flags):\n               ^^^^^^^^^^^^^^^^^^^^^^^^^^^^^^^^^^^^^^^^^^^^^^^^^^^^^^^^^^^\nsocket.gaierror: [Errno 8] nodename nor servname provided, or not known\n\nThe above exception was the direct cause of the following exception:\n\nTraceback (most recent call last):\n  File \"\/opt\/anaconda3\/lib\/python3.12\/site-packages\/urllib3\/connectionpool.py\", line 789, in urlopen\n    response = self._make_request(\n               ^^^^^^^^^^^^^^^^^^^\n  File \"\/opt\/anaconda3\/lib\/python3.12\/site-packages\/urllib3\/connectionpool.py\", line 490, in _make_request\n    raise new_e\n  File \"\/opt\/anaconda3\/lib\/python3.12\/site-packages\/urllib3\/connectionpool.py\", line 466, in _make_request\n    self._validate_conn(conn)\n  File \"\/opt\/anaconda3\/lib\/python3.12\/site-packages\/urllib3\/connectionpool.py\", line 1095, in _validate_conn\n    conn.connect()\n  File \"\/opt\/anaconda3\/lib\/python3.12\/site-packages\/urllib3\/connection.py\", line 615, in connect\n    self.sock = sock = self._new_conn()\n                       ^^^^^^^^^^^^^^^^\n  File \"\/opt\/anaconda3\/lib\/python3.12\/site-packages\/urllib3\/connection.py\", line 203, in _new_conn\n    raise NameResolutionError(self.host, self, e) from e\nurllib3.exceptions.NameResolutionError: <urllib3.connection.HTTPSConnection object at 0x11a21a3f0>: Failed to resolve 'anaconda.cloud' ([Errno 8] nodename nor servname provided, or not known)\n\nThe above exception was the direct cause of the following exception:\n\nTraceback (most recent call last):\n  File \"\/opt\/anaconda3\/lib\/python3.12\/site-packages\/requests\/adapters.py\", line 589, in send\n    resp = conn.urlopen(\n           ^^^^^^^^^^^^^\n  File \"\/opt\/anaconda3\/lib\/python3.12\/site-packages\/urllib3\/connectionpool.py\", line 843, in urlopen\n    retries = retries.increment(\n              ^^^^^^^^^^^^^^^^^^\n  File \"\/opt\/anaconda3\/lib\/python3.12\/site-packages\/urllib3\/util\/retry.py\", line 519, in increment\n    raise MaxRetryError(_pool, url, reason) from reason  # type: ignore[arg-type]\n    ^^^^^^^^^^^^^^^^^^^^^^^^^^^^^^^^^^^^^^^^^^^^^^^^^^^\nurllib3.exceptions.MaxRetryError: HTTPSConnectionPool(host='anaconda.cloud', port=443): Max retries exceeded with url: \/api\/account (Caused by NameResolutionError(\"<urllib3.connection.HTTPSConnection object at 0x11a21a3f0>: Failed to resolve 'anaconda.cloud' ([Errno 8] nodename nor servname provided, or not known)\"))\n\nDuring handling of the above exception, another exception occurred:\n\nTraceback (most recent call last):\n  File \"\/opt\/anaconda3\/lib\/python3.12\/site-packages\/anaconda_navigator\/api\/cloud\/api.py\", line 125, in __refresh_session\n    self.__account = self.account()\n                     ^^^^^^^^^^^^^^\n  File \"\/opt\/anaconda3\/lib\/python3.12\/site-packages\/anaconda_navigator\/utils\/workers.py\", line 652, in __call__\n    return self.__context(args=args, kwargs=kwargs).call()\n           ^^^^^^^^^^^^^^^^^^^^^^^^^^^^^^^^^^^^^^^^^^^^^^^\n  File \"\/opt\/anaconda3\/lib\/python3.12\/site-packages\/anaconda_navigator\/utils\/workers.py\", line 93, in __call__\n    return self.__function(*self.__args, **self.__kwargs)\n           ^^^^^^^^^^^^^^^^^^^^^^^^^^^^^^^^^^^^^^^^^^^^^^\n  File \"\/opt\/anaconda3\/lib\/python3.12\/site-packages\/anaconda_navigator\/api\/cloud\/api.py\", line 165, in account\n    return self.__session.request(\n           ^^^^^^^^^^^^^^^^^^^^^^^\n  File \"\/opt\/anaconda3\/lib\/python3.12\/site-packages\/anaconda_navigator\/api\/cloud\/utilities\/sessions.py\", line 157, in request\n    result: requests.Response = requests.request(  # pylint: disable=missing-timeout\n                                ^^^^^^^^^^^^^^^^^^^^^^^^^^^^^^^^^^^^^^^^^^^^^^^^^^^^\n  File \"\/opt\/anaconda3\/lib\/python3.12\/site-packages\/requests\/api.py\", line 59, in request\n    return session.request(method=method, url=url, **kwargs)\n           ^^^^^^^^^^^^^^^^^^^^^^^^^^^^^^^^^^^^^^^^^^^^^^^^^\n  File \"\/opt\/anaconda3\/lib\/python3.12\/site-packages\/requests\/sessions.py\", line 589, in request\n    resp = self.send(prep, **send_kwargs)\n           ^^^^^^^^^^^^^^^^^^^^^^^^^^^^^^\n  File \"\/opt\/anaconda3\/lib\/python3.12\/site-packages\/requests\/sessions.py\", line 703, in send\n    r = adapter.send(request, **kwargs)\n        ^^^^^^^^^^^^^^^^^^^^^^^^^^^^^^^\n  File \"\/opt\/anaconda3\/lib\/python3.12\/site-packages\/requests\/adapters.py\", line 622, in send\n    raise ConnectionError(e, request=request)\nrequests.exceptions.ConnectionError: HTTPSConnectionPool(host='anaconda.cloud', port=443): Max retries exceeded with url: \/api\/account (Caused by NameResolutionError(\"<urllib3.connection.HTTPSConnection object at 0x11a21a3f0>: Failed to resolve 'anaconda.cloud' ([Errno 8] nodename nor servname provided, or not known)\"))"}
{"time":"2024-10-22 11:08:01","level":"ERROR","module":"client_api","method":"_get_api_info","line":622,"path":"\/opt\/anaconda3\/lib\/python3.12\/site-packages\/anaconda_navigator\/api\/client_api.py","message":"HTTPSConnectionPool(host='api.anaconda.org', port=443): Max retries exceeded with url: \/ (Caused by NameResolutionError(\"<urllib3.connection.HTTPSConnection object at 0x11a179580>: Failed to resolve 'api.anaconda.org' ([Errno 8] nodename nor servname provided, or not known)\"))"}
{"time":"2024-10-22 11:08:10","level":"ERROR","module":"resources","method":"load_resource","line":27,"path":"\/opt\/anaconda3\/lib\/python3.12\/site-packages\/anaconda_navigator\/utils\/attribution\/resources.py","message":"Unable to fetch resource: https:\/\/anaconda.cloud\/api\/navigator\/v1\/simple-advertisement","exception":"Traceback (most recent call last):\n  File \"\/opt\/anaconda3\/lib\/python3.12\/site-packages\/urllib3\/connection.py\", line 196, in _new_conn\n    sock = connection.create_connection(\n           ^^^^^^^^^^^^^^^^^^^^^^^^^^^^^\n  File \"\/opt\/anaconda3\/lib\/python3.12\/site-packages\/urllib3\/util\/connection.py\", line 60, in create_connection\n    for res in socket.getaddrinfo(host, port, family, socket.SOCK_STREAM):\n               ^^^^^^^^^^^^^^^^^^^^^^^^^^^^^^^^^^^^^^^^^^^^^^^^^^^^^^^^^^\n  File \"\/opt\/anaconda3\/lib\/python3.12\/socket.py\", line 963, in getaddrinfo\n    for res in _socket.getaddrinfo(host, port, family, type, proto, flags):\n               ^^^^^^^^^^^^^^^^^^^^^^^^^^^^^^^^^^^^^^^^^^^^^^^^^^^^^^^^^^^\nsocket.gaierror: [Errno 8] nodename nor servname provided, or not known\n\nThe above exception was the direct cause of the following exception:\n\nTraceback (most recent call last):\n  File \"\/opt\/anaconda3\/lib\/python3.12\/site-packages\/urllib3\/connectionpool.py\", line 789, in urlopen\n    response = self._make_request(\n               ^^^^^^^^^^^^^^^^^^^\n  File \"\/opt\/anaconda3\/lib\/python3.12\/site-packages\/urllib3\/connectionpool.py\", line 490, in _make_request\n    raise new_e\n  File \"\/opt\/anaconda3\/lib\/python3.12\/site-packages\/urllib3\/connectionpool.py\", line 466, in _make_request\n    self._validate_conn(conn)\n  File \"\/opt\/anaconda3\/lib\/python3.12\/site-packages\/urllib3\/connectionpool.py\", line 1095, in _validate_conn\n    conn.connect()\n  File \"\/opt\/anaconda3\/lib\/python3.12\/site-packages\/urllib3\/connection.py\", line 615, in connect\n    self.sock = sock = self._new_conn()\n                       ^^^^^^^^^^^^^^^^\n  File \"\/opt\/anaconda3\/lib\/python3.12\/site-packages\/urllib3\/connection.py\", line 203, in _new_conn\n    raise NameResolutionError(self.host, self, e) from e\nurllib3.exceptions.NameResolutionError: <urllib3.connection.HTTPSConnection object at 0x13ebc4500>: Failed to resolve 'anaconda.cloud' ([Errno 8] nodename nor servname provided, or not known)\n\nThe above exception was the direct cause of the following exception:\n\nTraceback (most recent call last):\n  File \"\/opt\/anaconda3\/lib\/python3.12\/site-packages\/requests\/adapters.py\", line 589, in send\n    resp = conn.urlopen(\n           ^^^^^^^^^^^^^\n  File \"\/opt\/anaconda3\/lib\/python3.12\/site-packages\/urllib3\/connectionpool.py\", line 843, in urlopen\n    retries = retries.increment(\n              ^^^^^^^^^^^^^^^^^^\n  File \"\/opt\/anaconda3\/lib\/python3.12\/site-packages\/urllib3\/util\/retry.py\", line 519, in increment\n    raise MaxRetryError(_pool, url, reason) from reason  # type: ignore[arg-type]\n    ^^^^^^^^^^^^^^^^^^^^^^^^^^^^^^^^^^^^^^^^^^^^^^^^^^^\nurllib3.exceptions.MaxRetryError: HTTPSConnectionPool(host='anaconda.cloud', port=443): Max retries exceeded with url: \/api\/navigator\/v1\/simple-advertisement (Caused by NameResolutionError(\"<urllib3.connection.HTTPSConnection object at 0x13ebc4500>: Failed to resolve 'anaconda.cloud' ([Errno 8] nodename nor servname provided, or not known)\"))\n\nDuring handling of the above exception, another exception occurred:\n\nTraceback (most recent call last):\n  File \"\/opt\/anaconda3\/lib\/python3.12\/site-packages\/anaconda_navigator\/utils\/attribution\/resources.py\", line 21, in load_resource\n    response: requests.Response = requests.get(url, timeout=30)\n                                  ^^^^^^^^^^^^^^^^^^^^^^^^^^^^^\n  File \"\/opt\/anaconda3\/lib\/python3.12\/site-packages\/requests\/api.py\", line 73, in get\n    return request(\"get\", url, params=params, **kwargs)\n           ^^^^^^^^^^^^^^^^^^^^^^^^^^^^^^^^^^^^^^^^^^^^\n  File \"\/opt\/anaconda3\/lib\/python3.12\/site-packages\/requests\/api.py\", line 59, in request\n    return session.request(method=method, url=url, **kwargs)\n           ^^^^^^^^^^^^^^^^^^^^^^^^^^^^^^^^^^^^^^^^^^^^^^^^^\n  File \"\/opt\/anaconda3\/lib\/python3.12\/site-packages\/requests\/sessions.py\", line 589, in request\n    resp = self.send(prep, **send_kwargs)\n           ^^^^^^^^^^^^^^^^^^^^^^^^^^^^^^\n  File \"\/opt\/anaconda3\/lib\/python3.12\/site-packages\/requests\/sessions.py\", line 703, in send\n    r = adapter.send(request, **kwargs)\n        ^^^^^^^^^^^^^^^^^^^^^^^^^^^^^^^\n  File \"\/opt\/anaconda3\/lib\/python3.12\/site-packages\/requests\/adapters.py\", line 622, in send\n    raise ConnectionError(e, request=request)\nrequests.exceptions.ConnectionError: HTTPSConnectionPool(host='anaconda.cloud', port=443): Max retries exceeded with url: \/api\/navigator\/v1\/simple-advertisement (Caused by NameResolutionError(\"<urllib3.connection.HTTPSConnection object at 0x13ebc4500>: Failed to resolve 'anaconda.cloud' ([Errno 8] nodename nor servname provided, or not known)\"))"}
